2018-12-08 17:08:01.562044: I tensorflow/core/platform/cpu_feature_guard.cc:141] Your CPU supports instructions that this TensorFlow binary was not compiled to use: AVX2 FMA
initializing system parameters
--------------Starting training  predictions_1d_conv_decrease0.001
Fold:  0
##################################################
Epoch 1/50
Using TensorFlow backend.
main.py:148: SettingWithCopyWarning: 
A value is trying to be set on a copy of a slice from a DataFrame.
Try using .loc[row_indexer,col_indexer] = value instead

See the caveats in the documentation: http://pandas.pydata.org/pandas-docs/stable/indexing.html#indexing-view-versus-copy
  train["actual_label_idx"] = train.label.apply(lambda x: label_idx[x])

1/3 [=========>....................] - ETA: 1:15 - loss: 0.6934 - acc: 0.3906
2/3 [===================>..........] - ETA: 36s - loss: 0.6932 - acc: 0.4609 
3/3 [==============================] - 133s 44s/step - loss: 0.6951 - acc: 0.4203 - val_loss: 0.6924 - val_acc: 0.5056

Epoch 00001: val_loss improved from inf to 0.69235, saving model to ../models/predictions_1d_conv_decrease0.001/best_0.h5
Traceback (most recent call last):
  File "main.py", line 159, in <module>
    main()
  File "main.py", line 155, in main
    train_network(network_names[i]+str(l),lst_of_networks[i],config, train, test, LABELS, num_cores)
  File "main.py", line 72, in train_network
    epochs=config.max_epochs, use_multiprocessing=True, workers=num_cores, max_queue_size=20)
  File "/Users/mahapsub/.local/lib/python3.6/site-packages/keras/legacy/interfaces.py", line 91, in wrapper
    return func(*args, **kwargs)
  File "/Users/mahapsub/.local/lib/python3.6/site-packages/keras/engine/training.py", line 1418, in fit_generator
    initial_epoch=initial_epoch)
  File "/Users/mahapsub/.local/lib/python3.6/site-packages/keras/engine/training_generator.py", line 251, in fit_generator
    callbacks.on_epoch_end(epoch, epoch_logs)
  File "/Users/mahapsub/.local/lib/python3.6/site-packages/keras/callbacks.py", line 79, in on_epoch_end
    callback.on_epoch_end(epoch, logs)
  File "/Users/mahapsub/.local/lib/python3.6/site-packages/keras/callbacks.py", line 446, in on_epoch_end
    self.model.save(filepath, overwrite=True)
  File "/Users/mahapsub/.local/lib/python3.6/site-packages/keras/engine/network.py", line 1090, in save
    save_model(self, filepath, overwrite, include_optimizer)
  File "/Users/mahapsub/.local/lib/python3.6/site-packages/keras/engine/saving.py", line 379, in save_model
    f = h5dict(filepath, mode='w')
  File "/Users/mahapsub/.local/lib/python3.6/site-packages/keras/utils/io_utils.py", line 186, in __init__
    self.data = h5py.File(path, mode=mode)
  File "/Users/mahapsub/.local/lib/python3.6/site-packages/h5py/_hl/files.py", line 312, in __init__
    fid = make_fid(name, mode, userblock_size, fapl, swmr=swmr)
  File "/Users/mahapsub/.local/lib/python3.6/site-packages/h5py/_hl/files.py", line 148, in make_fid
    fid = h5f.create(name, h5f.ACC_TRUNC, fapl=fapl, fcpl=fcpl)
  File "h5py/_objects.pyx", line 54, in h5py._objects.with_phil.wrapper
  File "h5py/_objects.pyx", line 55, in h5py._objects.with_phil.wrapper
  File "h5py/h5f.pyx", line 98, in h5py.h5f.create
OSError: Unable to create file (unable to open file: name = '../models/predictions_1d_conv_decrease0.001/best_0.h5', errno = 2, error message = 'No such file or directory', flags = 13, o_flags = 602)
