2018-12-08 20:10:26.683407: I tensorflow/core/platform/cpu_feature_guard.cc:141] Your CPU supports instructions that this TensorFlow binary was not compiled to use: AVX2 FMA
initializing system parameters
--------------Starting training  predictions_1d_conv_activ_exp0.001
Fold:  0
##################################################
Epoch 1/50
Using TensorFlow backend.
main.py:148: SettingWithCopyWarning: 
A value is trying to be set on a copy of a slice from a DataFrame.
Try using .loc[row_indexer,col_indexer] = value instead

See the caveats in the documentation: http://pandas.pydata.org/pandas-docs/stable/indexing.html#indexing-view-versus-copy
  train["actual_label_idx"] = train.label.apply(lambda x: label_idx[x])

1/3 [=========>....................] - ETA: 10s - loss: nan - acc: 0.5156
2/3 [===================>..........] - ETA: 2s - loss: nan - acc: 0.4870 
3/3 [==============================] - 9s 3s/step - loss: nan - acc: 0.4974 - val_loss: nan - val_acc: 0.5000

Epoch 00001: val_loss did not improve from inf
Epoch 2/50

1/3 [=========>....................] - ETA: 4s - loss: nan - acc: 0.4583
2/3 [===================>..........] - ETA: 1s - loss: nan - acc: 0.4870
3/3 [==============================] - 7s 2s/step - loss: nan - acc: 0.4974 - val_loss: nan - val_acc: 0.5000

Epoch 00002: val_loss did not improve from inf
Epoch 3/50

1/3 [=========>....................] - ETA: 6s - loss: nan - acc: 0.5156
2/3 [===================>..........] - ETA: 2s - loss: nan - acc: 0.4870
3/3 [==============================] - 7s 2s/step - loss: nan - acc: 0.4974 - val_loss: nan - val_acc: 0.5000

Epoch 00003: val_loss did not improve from inf
Traceback (most recent call last):
  File "main.py", line 159, in <module>
    main()
  File "main.py", line 155, in main
    train_network(network_names[i]+str(l),lst_of_networks[i],config, train, test, LABELS, num_cores)
  File "main.py", line 74, in train_network
    model.load_weights(MODEL_PATH+'best_%d.h5' % i)
  File "/Users/mahapsub/.local/lib/python3.6/site-packages/keras/engine/network.py", line 1157, in load_weights
    with h5py.File(filepath, mode='r') as f:
  File "/Users/mahapsub/.local/lib/python3.6/site-packages/h5py/_hl/files.py", line 312, in __init__
    fid = make_fid(name, mode, userblock_size, fapl, swmr=swmr)
  File "/Users/mahapsub/.local/lib/python3.6/site-packages/h5py/_hl/files.py", line 142, in make_fid
    fid = h5f.open(name, flags, fapl=fapl)
  File "h5py/_objects.pyx", line 54, in h5py._objects.with_phil.wrapper
  File "h5py/_objects.pyx", line 55, in h5py._objects.with_phil.wrapper
  File "h5py/h5f.pyx", line 78, in h5py.h5f.open
OSError: Unable to open file (unable to open file: name = 'models/predictions_1d_conv_activ_exp0.001/best_0.h5', errno = 2, error message = 'No such file or directory', flags = 0, o_flags = 0)
